<mujoco model="gen3_lite_gen3_lite_2f">
  <compiler angle="radian"/>

  <option timestep="0.002" gravity="0 0 -9.81"/>

  <default>
    <joint damping="0.5" frictionloss="0.1"/>
  </default>

  <asset>
    <mesh name="base_link" content_type="model/stl" file="base_link.STL"/>
    <mesh name="shoulder_link" content_type="model/stl" file="shoulder_link.STL"/>
    <mesh name="arm_link" content_type="model/stl" file="arm_link.STL"/>
    <mesh name="forearm_link" content_type="model/stl" file="forearm_link.STL"/>
    <mesh name="lower_wrist_link" content_type="model/stl" file="lower_wrist_link.STL"/>
    <mesh name="upper_wrist_link" content_type="model/stl" file="upper_wrist_link.STL"/>
    <mesh name="gripper_base_link" content_type="model/stl" file="gripper_base_link.STL"/>
    <mesh name="right_finger_prox_link" content_type="model/stl" file="right_finger_prox_link.STL"/>
    <mesh name="right_finger_dist_link" content_type="model/stl" file="right_finger_dist_link.STL"/>
    <mesh name="left_finger_prox_link" content_type="model/stl" file="left_finger_prox_link.STL"/>
    <mesh name="left_finger_dist_link" content_type="model/stl" file="left_finger_dist_link.STL"/>
  </asset>

  <worldbody>
    <geom type="mesh" rgba="0.803 0.824 0.82 1" mesh="base_link"/>
    <camera mode="fixed" name="robotview1" pos="0.0 -2.0 0.5" quat="0.7071 0.7071 0 0"/>
    <camera mode="fixed" name="robotview2" pos="0.0 2.0 0.5" quat="0 0 0.7071 0.7071"/>
    <body name="shoulder_link" pos="0 0 0.12825">

      <inertial pos="2.477e-05 0.0221353 0.0993769" quat="0.972429 0.233194 -0.000430944 0.00108761" mass="0.959744" diaginertia="0.00165947 0.00158128 0.000717195"/>
      <joint name="joint_1" pos="0 0 0" axis="0 0 1" range="-2.68 2.68" actuatorfrcrange="-10 10"/>
      <geom type="mesh" rgba="0.803 0.824 0.82 1" mesh="shoulder_link"/>
      <body name="arm_link" pos="0 -0.03 0.115" quat="0.707105 0.707108 0 0">
        <inertial pos="0.029983 0.211548 0.0453031" quat="0.534676 0.467794 -0.46336 0.529706" mass="1.17756" diaginertia="0.0115237 0.0114928 0.000839712"/>
        <joint name="joint_2" pos="0 0 0" axis="0 0 1" range="-2.61 2.61" actuatorfrcrange="-14 14"/>
        <geom type="mesh" rgba="0.803 0.824 0.82 1" mesh="arm_link"/>
        <body name="forearm_link" pos="0 0.28 0" quat="-3.67321e-06 -1 0 0">
          <inertial pos="0.0301559 0.0950221 0.0073555" quat="0.523543 0.49139 -0.473675 0.50997" mass="0.597677" diaginertia="0.00169754 0.00163253 0.000291376"/>
          <joint name="joint_3" pos="0 0 0" axis="0 0 1" range="-2.61 2.61" actuatorfrcrange="-10 10"/>
          <geom type="mesh" rgba="0.803 0.824 0.82 1" mesh="forearm_link"/>
          <body name="lower_wrist_link" pos="0 -0.14 0.02" quat="0.707105 0.707108 0 0">
            <inertial pos="0.00575149 0.0100044 0.0871921" quat="0.700403 -0.13124 -0.134345 0.688595" mass="0.526934" diaginertia="0.000785199 0.000756398 0.000275722"/>
            <joint name="joint_4" pos="0 0 0" axis="0 0 1" range="-2.6 2.6" actuatorfrcrange="-7 7"/>
            <geom type="mesh" rgba="0.803 0.824 0.82 1" mesh="lower_wrist_link"/>
            <body name="upper_wrist_link" pos="0.0285 0 0.105" quat="0.707105 0 0.707108 0">
              <inertial pos="0.0805652 0.00980409 0.018728" quat="0.00431726 0.708285 -4.18922e-06 0.705913" mass="0.580973" diaginertia="0.00108466 0.00106374 0.000212638"/>
              <joint name="joint_5" pos="0 0 0" axis="0 0 1" range="-2.53 2.53" actuatorfrcrange="-7 7"/>
              <geom type="mesh" rgba="0.803 0.824 0.82 1" mesh="upper_wrist_link"/>
              <body name="end_effector_link" pos="-0.105 0 0.0285" quat="0.707105 0 -0.707108 0">
                <joint name="joint_6" pos="0 0 0" axis="0 0 1" range="-2.6 2.6" actuatorfrcrange="-7 7"/>
                <geom type="mesh" rgba="0.803 0.824 0.82 1" mesh="gripper_base_link"/>
                <body name="right_finger_prox_link" pos="0 -0.030501 0.070003" quat="0.707105 0 0.707108 0">
                  <inertial pos="0.020257 0.0063483 6.991e-05" quat="0.598941 0.598941 0.375858 0.375858" mass="0.018385" diaginertia="5.25068e-06 4.77e-06 1.59932e-06"/>
                  <joint name="right_finger_bottom_joint" pos="0 0 0" axis="0 0 1" range="-0.09 0.96" actuatorfrcrange="-1000 1000"/>
                  <geom type="mesh" rgba="0.803 0.824 0.82 1" mesh="right_finger_prox_link"/>
                  <body name="right_finger_dist_link" pos="-0.045636 0.020423 0">
                    <inertial pos="0.018488 0.0011091 0" quat="0.557345 0.557345 0.435162 0.435162" mass="0.010748" diaginertia="1.91e-06 1.61e-06 5.5e-07"/>
                    <joint name="right_finger_tip_joint" pos="0 0 0" axis="0 0 1" range="-0.5 0.21" actuatorfrcrange="-1000 1000"/>
                    <geom type="mesh" rgba="0 0.055 0.525 1" mesh="right_finger_dist_link"/>
                  </body>
                </body>
                <body name="left_finger_prox_link" pos="0 0.0305 0.070003" quat="0.707105 0 0.707108 0">
                  <inertial pos="0.020257 0.0063483 6.99e-05" quat="0.598941 0.598941 0.375858 0.375858" mass="0.018385" diaginertia="5.25068e-06 4.77e-06 1.59932e-06"/>
                  <joint name="left_finger_bottom_joint" pos="0 0 0" axis="0 0 1" range="-0.96 0.09" actuatorfrcrange="-1000 1000"/>
                  <geom type="mesh" rgba="0.803 0.824 0.82 1" mesh="left_finger_prox_link"/>
                  <body name="left_finger_dist_link" pos="-0.045636 -0.020423 6.9901e-05">
                    <inertial pos="-0.018488 0.0011091 0" quat="0.557345 0.557345 0.435162 0.435162" mass="0.010748" diaginertia="1.91e-06 1.61e-06 5.5e-07"/>
                    <joint name="left_finger_tip_joint" pos="0 0 0" axis="0 0 -1" range="-0.5 0.21" actuatorfrcrange="-1000 1000"/>
                    <geom type="mesh" rgba="0 0.055 0.525 1" mesh="left_finger_dist_link"/>
                  </body>
                </body>
              </body>
            </body>
          </body>
        </body>
      </body>
    </body>
  </worldbody>

  <actuator>
    <position name="joint_1" joint="joint_1" kp="800"/>
    <position name="joint_2" joint="joint_2" kp="800"/>
    <position name="joint_3" joint="joint_3" kp="500"/>
    <position name="joint_4" joint="joint_4" kp="100"/>
    <position name="joint_5" joint="joint_5" kp="100"/>
    <position name="joint_6" joint="joint_6" kp="100"/>

    <position name="gripper_right" joint="right_finger_bottom_joint" kp="100"/>
    <position name="gripper_left" joint="left_finger_bottom_joint" kp="100"/>
  </actuator>
</mujoco>